<?xml version="1.0" ?>
<!-- =================================================================================== -->
<!-- |    This document was autogenerated by xacro from /root/catkin_ws/src/abb_irb2600_12_185_dual_support/urdf/abb_irb2600_dual.xacro | -->
<!-- |    EDITING THIS FILE BY HAND IS NOT RECOMMENDED                                 | -->
<!-- =================================================================================== -->
<robot name="mid_robot_dual_cell">
    <!-- Conversion were obtained from http://www.e-paint.co.uk/Lab_values.asp
       unless otherwise stated. -->
    <!-- link list -->
    <link name="robotA_base_link">
        <collision>
            <origin quat="0 0 0 1" xyz="0 0 0" />
            <geometry>
                <mesh filename="package://abb_irb2600_12_185_dual_support/meshes/collision/BaseLink.stl" />
            </geometry>
        </collision>
        <visual>
            <origin quat="0 0 0 1" xyz="0 0 0" />
            <geometry>
                <mesh filename="package://abb_irb2600_12_185_dual_support/meshes/visual/BaseLink.stl" />
            </geometry>
            <material name="">
                <color rgba="0.3450980 0.3647059 0.3686275 1" />
            </material>
        </visual>
        <inertial>
            <mass value="0.1" />
            <origin xyz="0 0 0" rpy="0 0 0" />
            <inertia ixx="0.03" iyy="0.03" izz="0.03" ixy="0.0" ixz="0.0" iyz="0.0" />
        </inertial>
    </link>
    <link name="robotA_link_1">
        <collision>
            <origin quat="0 0 0 1" xyz="0 0 -0.445" />
            <geometry>
                <mesh filename="package://abb_irb2600_12_185_dual_support/meshes/collision/Link1.stl" />
            </geometry>
        </collision>
        <visual>
            <origin quat="0 0 0 1" xyz="0 0 -0.445" />
            <geometry>
                <mesh filename="package://abb_irb2600_12_185_dual_support/meshes/visual/Link1.stl" />
            </geometry>
            <material name="">
                <color rgba="0.3450980 0.3647059 0.3686275 1" />
            </material>
        </visual>
        <inertial>
            <mass value="0.1" />
            <origin xyz="0 0 0" rpy="0 0 0" />
            <inertia ixx="0.03" iyy="0.03" izz="0.03" ixy="0.0" ixz="0.0" iyz="0.0" />
        </inertial>
    </link>
    <link name="robotA_link_2">
        <collision>
            <origin quat="0 0 0 1" xyz="-0.15 0 -0.445" />
            <geometry>
                <mesh filename="package://abb_irb2600_12_185_dual_support/meshes/collision/Link2.stl" />
            </geometry>
        </collision>
        <visual>
            <origin quat="0 0 0 1" xyz="-0.15 0 -0.445" />
            <geometry>
                <mesh filename="package://abb_irb2600_12_185_dual_support/meshes/visual/Link2.stl" />
            </geometry>
            <material name="">
                <color rgba="0.3450980 0.3647059 0.3686275 1" />
            </material>
        </visual>
        <inertial>
            <mass value="0.1" />
            <origin xyz="0 0 0" rpy="0 0 0" />
            <inertia ixx="0.03" iyy="0.03" izz="0.03" ixy="0.0" ixz="0.0" iyz="0.0" />
        </inertial>
    </link>
    <link name="robotA_link_3">
        <collision>
            <origin quat="0 0 0 1" xyz="-0.15 0 -1.345" />
            <geometry>
                <mesh filename="package://abb_irb2600_12_185_dual_support/meshes/collision/Link3.stl" />
            </geometry>
        </collision>
        <visual>
            <origin quat="0 0 0 1" xyz="-0.15 0 -1.345" />
            <geometry>
                <mesh filename="package://abb_irb2600_12_185_dual_support/meshes/visual/Link3.stl" />
            </geometry>
            <material name="">
                <color rgba="0.3450980 0.3647059 0.3686275 1" />
            </material>
        </visual>
        <inertial>
            <mass value="0.1" />
            <origin xyz="0 0 0" rpy="0 0 0" />
            <inertia ixx="0.03" iyy="0.03" izz="0.03" ixy="0.0" ixz="0.0" iyz="0.0" />
        </inertial>
    </link>
    <link name="robotA_link_4">
        <collision>
            <origin quat="0 0 0 1" xyz="-0.15 0 -1.46" />
            <geometry>
                <mesh filename="package://abb_irb2600_12_185_dual_support/meshes/collision/Link4.stl" />
            </geometry>
        </collision>
        <visual>
            <origin quat="0 0 0 1" xyz="-0.15 0 -1.46" />
            <geometry>
                <mesh filename="package://abb_irb2600_12_185_dual_support/meshes/visual/Link4.stl" />
            </geometry>
            <material name="">
                <color rgba="0.7725490 0.7803922 0.7686275 1" />
            </material>
        </visual>
        <inertial>
            <mass value="0.1" />
            <origin xyz="0 0 0" rpy="0 0 0" />
            <inertia ixx="0.03" iyy="0.03" izz="0.03" ixy="0.0" ixz="0.0" iyz="0.0" />
        </inertial>
    </link>
    <link name="robotA_link_5">
        <collision>
            <origin quat="0 0 0 1" xyz="-0.945 0 -1.46" />
            <geometry>
                <mesh filename="package://abb_irb2600_12_185_dual_support/meshes/collision/Link5.stl" />
            </geometry>
        </collision>
        <visual>
            <origin quat="0 0 0 1" xyz="-0.945 0 -1.46" />
            <geometry>
                <mesh filename="package://abb_irb2600_12_185_dual_support/meshes/visual/Link5.stl" />
            </geometry>
            <material name="">
                <color rgba="0.7725490 0.7803922 0.7686275 1" />
            </material>
        </visual>
        <inertial>
            <mass value="0.1" />
            <origin xyz="0 0 0" rpy="0 0 0" />
            <inertia ixx="0.03" iyy="0.03" izz="0.03" ixy="0.0" ixz="0.0" iyz="0.0" />
        </inertial>
    </link>
    <link name="robotA_link_6">
        <collision>
            <origin quat="0 0 0 1" xyz="-1.03 0 -1.46" />
            <geometry>
                <mesh filename="package://abb_irb2600_12_185_dual_support/meshes/collision/Link6.stl" />
            </geometry>
        </collision>
        <visual>
            <origin quat="0 0 0 1" xyz="-1.03 0 -1.46" />
            <geometry>
                <mesh filename="package://abb_irb2600_12_185_dual_support/meshes/visual/Link6.stl" />
            </geometry>
            <material name="">
                <color rgba="0.8392157 0.8352941 0.7921569 1" />
            </material>
        </visual>
        <inertial>
            <mass value="0.1" />
            <origin xyz="0 0 0" rpy="0 0 0" />
            <inertia ixx="0.03" iyy="0.03" izz="0.03" ixy="0.0" ixz="0.0" iyz="0.0" />
        </inertial>
    </link>
    <!-- end of link list -->
    <!-- joint list -->
    <joint name="robotA_joint_1" type="revolute">
        <origin quat="0 0 0 1" xyz="0.000 0.000 0.445" />
        <axis xyz="0 0 1" />
        <parent link="robotA_base_link" />
        <child link="robotA_link_1" />
        <limit acceleration="15.27" effort="0.0" lower="-3.1215" upper="3.12159" velocity="3.054" />
    </joint>
    <joint name="robotA_joint_2" type="revolute">
        <origin quat="0 0 0 1" xyz="0.150 0.000 0.000" />
        <axis xyz="0 1 0" />
        <parent link="robotA_link_1" />
        <child link="robotA_link_2" />
        <limit acceleration="15.27" effort="0.0" lower="-1.638" upper="2.685" velocity="3.054" />
    </joint>
    <joint name="robotA_joint_3" type="revolute">
        <origin quat="0 0 0 1" xyz="0.000 0.000 0.900" />
        <axis xyz="0 1 0" />
        <parent link="robotA_link_2" />
        <child link="robotA_link_3" />
        <limit acceleration="15.27" effort="0.0" lower="-3.12159" upper="1.289" velocity="3.054" />
    </joint>
    <joint name="robotA_joint_4" type="revolute">
        <origin quat="0 0 0 1" xyz="0.000 0.000 0.115" />
        <axis xyz="1 0 0" />
        <parent link="robotA_link_3" />
        <child link="robotA_link_4" />
        <limit acceleration="31.4150" effort="0.0" lower="-6.961" upper="6.961" velocity="6.283" />
    </joint>
    <joint name="robotA_joint_5" type="revolute">
        <origin quat="0 0 0 1" xyz="0.795 0.000 0.000" />
        <axis xyz="0 1 0" />
        <parent link="robotA_link_4" />
        <child link="robotA_link_5" />
        <limit acceleration="31.4150" effort="0.0" lower="-2.074" upper="2.074" velocity="6.283" />
    </joint>
    <joint name="robotA_joint_6" type="revolute">
        <origin quat="0 0 0 1" xyz="0.085 0.000 0.000" />
        <axis xyz="1 0 0" />
        <parent link="robotA_link_5" />
        <child link="robotA_link_6" />
        <limit acceleration="43.6350" effort="0.0" lower="-6.961" upper="6.961" velocity="8.727" />
    </joint>
    <!-- end of joint list -->
    <!-- ROS-Industrial 'base' frame: base_link to ABB World Coordinates transform -->
    <link name="robotA_base" />
    <joint name="robotA_base_link-base" type="fixed">
        <origin rpy="0 0 0" xyz="0 0 0" />
        <parent link="robotA_base_link" />
        <child link="robotA_base" />
    </joint>
    <!-- ROS-Industrial 'flange' frame: attachment point for EEF models -->
    <link name="robotA_flange" />
    <joint name="robotA_joint_6-flange" type="fixed">
        <origin rpy="0 0 0" xyz="0 0 0" />
        <parent link="robotA_link_6" />
        <child link="robotA_flange" />
    </joint>
    <!-- ROS-Industrial 'tool0' frame: all-zeros tool frame -->
    <link name="robotA_tool0" />
    <joint name="robotA_flange-tool0" type="fixed">
        <origin rpy="0 1.5707963267948966 0" xyz="0 0 0" />
        <parent link="robotA_flange" />
        <child link="robotA_tool0" />
    </joint>
    <!-- link list -->
    <link name="robotB_base_link">
        <collision>
            <origin quat="0 0 0 1" xyz="0 0 0" />
            <geometry>
                <mesh filename="package://abb_irb2600_12_185_dual_support/meshes/collision/BaseLink.stl" />
            </geometry>
        </collision>
        <visual>
            <origin quat="0 0 0 1" xyz="0 0 0" />
            <geometry>
                <mesh filename="package://abb_irb2600_12_185_dual_support/meshes/visual/BaseLink.stl" />
            </geometry>
            <material name="">
                <color rgba="0.3450980 0.3647059 0.3686275 1" />
            </material>
        </visual>
        <inertial>
            <mass value="0.1" />
            <origin xyz="0 0 0" rpy="0 0 0" />
            <inertia ixx="0.03" iyy="0.03" izz="0.03" ixy="0.0" ixz="0.0" iyz="0.0" />
        </inertial>
    </link>
    <link name="robotB_link_1">
        <collision>
            <origin quat="0 0 0 1" xyz="0 0 -0.445" />
            <geometry>
                <mesh filename="package://abb_irb2600_12_185_dual_support/meshes/collision/Link1.stl" />
            </geometry>
        </collision>
        <visual>
            <origin quat="0 0 0 1" xyz="0 0 -0.445" />
            <geometry>
                <mesh filename="package://abb_irb2600_12_185_dual_support/meshes/visual/Link1.stl" />
            </geometry>
            <material name="">
                <color rgba="0.3450980 0.3647059 0.3686275 1" />
            </material>
        </visual>
        <inertial>
            <mass value="0.1" />
            <origin xyz="0 0 0" rpy="0 0 0" />
            <inertia ixx="0.03" iyy="0.03" izz="0.03" ixy="0.0" ixz="0.0" iyz="0.0" />
        </inertial>
    </link>
    <link name="robotB_link_2">
        <collision>
            <origin quat="0 0 0 1" xyz="-0.15 0 -0.445" />
            <geometry>
                <mesh filename="package://abb_irb2600_12_185_dual_support/meshes/collision/Link2.stl" />
            </geometry>
        </collision>
        <visual>
            <origin quat="0 0 0 1" xyz="-0.15 0 -0.445" />
            <geometry>
                <mesh filename="package://abb_irb2600_12_185_dual_support/meshes/visual/Link2.stl" />
            </geometry>
            <material name="">
                <color rgba="0.3450980 0.3647059 0.3686275 1" />
            </material>
        </visual>
        <inertial>
            <mass value="0.1" />
            <origin xyz="0 0 0" rpy="0 0 0" />
            <inertia ixx="0.03" iyy="0.03" izz="0.03" ixy="0.0" ixz="0.0" iyz="0.0" />
        </inertial>
    </link>
    <link name="robotB_link_3">
        <collision>
            <origin quat="0 0 0 1" xyz="-0.15 0 -1.345" />
            <geometry>
                <mesh filename="package://abb_irb2600_12_185_dual_support/meshes/collision/Link3.stl" />
            </geometry>
        </collision>
        <visual>
            <origin quat="0 0 0 1" xyz="-0.15 0 -1.345" />
            <geometry>
                <mesh filename="package://abb_irb2600_12_185_dual_support/meshes/visual/Link3.stl" />
            </geometry>
            <material name="">
                <color rgba="0.3450980 0.3647059 0.3686275 1" />
            </material>
        </visual>
        <inertial>
            <mass value="0.1" />
            <origin xyz="0 0 0" rpy="0 0 0" />
            <inertia ixx="0.03" iyy="0.03" izz="0.03" ixy="0.0" ixz="0.0" iyz="0.0" />
        </inertial>
    </link>
    <link name="robotB_link_4">
        <collision>
            <origin quat="0 0 0 1" xyz="-0.15 0 -1.46" />
            <geometry>
                <mesh filename="package://abb_irb2600_12_185_dual_support/meshes/collision/Link4.stl" />
            </geometry>
        </collision>
        <visual>
            <origin quat="0 0 0 1" xyz="-0.15 0 -1.46" />
            <geometry>
                <mesh filename="package://abb_irb2600_12_185_dual_support/meshes/visual/Link4.stl" />
            </geometry>
            <material name="">
                <color rgba="0.7725490 0.7803922 0.7686275 1" />
            </material>
        </visual>
        <inertial>
            <mass value="0.1" />
            <origin xyz="0 0 0" rpy="0 0 0" />
            <inertia ixx="0.03" iyy="0.03" izz="0.03" ixy="0.0" ixz="0.0" iyz="0.0" />
        </inertial>
    </link>
    <link name="robotB_link_5">
        <collision>
            <origin quat="0 0 0 1" xyz="-0.945 0 -1.46" />
            <geometry>
                <mesh filename="package://abb_irb2600_12_185_dual_support/meshes/collision/Link5.stl" />
            </geometry>
        </collision>
        <visual>
            <origin quat="0 0 0 1" xyz="-0.945 0 -1.46" />
            <geometry>
                <mesh filename="package://abb_irb2600_12_185_dual_support/meshes/visual/Link5.stl" />
            </geometry>
            <material name="">
                <color rgba="0.7725490 0.7803922 0.7686275 1" />
            </material>
        </visual>
        <inertial>
            <mass value="0.1" />
            <origin xyz="0 0 0" rpy="0 0 0" />
            <inertia ixx="0.03" iyy="0.03" izz="0.03" ixy="0.0" ixz="0.0" iyz="0.0" />
        </inertial>
    </link>
    <link name="robotB_link_6">
        <collision>
            <origin quat="0 0 0 1" xyz="-1.03 0 -1.46" />
            <geometry>
                <mesh filename="package://abb_irb2600_12_185_dual_support/meshes/collision/Link6.stl" />
            </geometry>
        </collision>
        <visual>
            <origin quat="0 0 0 1" xyz="-1.03 0 -1.46" />
            <geometry>
                <mesh filename="package://abb_irb2600_12_185_dual_support/meshes/visual/Link6.stl" />
            </geometry>
            <material name="">
                <color rgba="0.8392157 0.8352941 0.7921569 1" />
            </material>
        </visual>
        <inertial>
            <mass value="0.1" />
            <origin xyz="0 0 0" rpy="0 0 0" />
            <inertia ixx="0.03" iyy="0.03" izz="0.03" ixy="0.0" ixz="0.0" iyz="0.0" />
        </inertial>
    </link>
    <!-- end of link list -->
    <!-- joint list -->
    <joint name="robotB_joint_1" type="revolute">
        <origin quat="0 0 0 1" xyz="0.000 0.000 0.445" />
        <axis xyz="0 0 1" />
        <parent link="robotB_base_link" />
        <child link="robotB_link_1" />
        <limit acceleration="15.27" effort="0.0" lower="-3.1215" upper="3.12159" velocity="3.054" />
    </joint>
    <joint name="robotB_joint_2" type="revolute">
        <origin quat="0 0 0 1" xyz="0.150 0.000 0.000" />
        <axis xyz="0 1 0" />
        <parent link="robotB_link_1" />
        <child link="robotB_link_2" />
        <limit acceleration="15.27" effort="0.0" lower="-1.638" upper="2.685" velocity="3.054" />
    </joint>
    <joint name="robotB_joint_3" type="revolute">
        <origin quat="0 0 0 1" xyz="0.000 0.000 0.900" />
        <axis xyz="0 1 0" />
        <parent link="robotB_link_2" />
        <child link="robotB_link_3" />
        <limit acceleration="15.27" effort="0.0" lower="-3.12159" upper="1.289" velocity="3.054" />
    </joint>
    <joint name="robotB_joint_4" type="revolute">
        <origin quat="0 0 0 1" xyz="0.000 0.000 0.115" />
        <axis xyz="1 0 0" />
        <parent link="robotB_link_3" />
        <child link="robotB_link_4" />
        <limit acceleration="31.4150" effort="0.0" lower="-6.961" upper="6.961" velocity="6.283" />
    </joint>
    <joint name="robotB_joint_5" type="revolute">
        <origin quat="0 0 0 1" xyz="0.795 0.000 0.000" />
        <axis xyz="0 1 0" />
        <parent link="robotB_link_4" />
        <child link="robotB_link_5" />
        <limit acceleration="31.4150" effort="0.0" lower="-2.074" upper="2.074" velocity="6.283" />
    </joint>
    <joint name="robotB_joint_6" type="revolute">
        <origin quat="0 0 0 1" xyz="0.085 0.000 0.000" />
        <axis xyz="1 0 0" />
        <parent link="robotB_link_5" />
        <child link="robotB_link_6" />
        <limit acceleration="43.6350" effort="0.0" lower="-6.961" upper="6.961" velocity="8.727" />
    </joint>
    <!-- end of joint list -->
    <!-- ROS-Industrial 'base' frame: base_link to ABB World Coordinates transform -->
    <link name="robotB_base" />
    <joint name="robotB_base_link-base" type="fixed">
        <origin rpy="0 0 0" xyz="0 0 0" />
        <parent link="robotB_base_link" />
        <child link="robotB_base" />
    </joint>
    <!-- ROS-Industrial 'flange' frame: attachment point for EEF models -->
    <link name="robotB_flange" />
    <joint name="robotB_joint_6-flange" type="fixed">
        <origin rpy="0 0 0" xyz="0 0 0" />
        <parent link="robotB_link_6" />
        <child link="robotB_flange" />
    </joint>
    <!-- ROS-Industrial 'tool0' frame: all-zeros tool frame -->
    <link name="robotB_tool0" />
    <joint name="robotB_flange-tool0" type="fixed">
        <origin rpy="0 1.5707963267948966 0" xyz="0 0 0" />
        <parent link="robotB_flange" />
        <child link="robotB_tool0" />
    </joint>
    <link name="world" />
    <joint name="robotA_joint" type="fixed">
        <parent link="world" />
        <child link="robotA_base_link" />
        <origin rpy="0 0 0" xyz="0 0 0" />
    </joint>
    <joint name="robotB_joint" type="fixed">
        <parent link="world" />
        <child link="robotB_base_link" />
        <origin rpy="-0 0 -3.1415926" xyz="2.5 0 0" />
    </joint>
    <transmission name="trans_robotA_joint_1">
        <type>transmission_interface/SimpleTransmission</type>
        <joint name="robotA_joint_1">
            <hardwareInterface>hardware_interface/EffortJointInterface</hardwareInterface>
        </joint>
        <actuator name="robotA_joint_1_motor">
            <hardwareInterface>hardware_interface/EffortJointInterface</hardwareInterface>
            <mechanicalReduction>1</mechanicalReduction>
        </actuator>
    </transmission>
    <transmission name="trans_robotA_joint_2">
        <type>transmission_interface/SimpleTransmission</type>
        <joint name="robotA_joint_2">
            <hardwareInterface>hardware_interface/EffortJointInterface</hardwareInterface>
        </joint>
        <actuator name="robotA_joint_2_motor">
            <hardwareInterface>hardware_interface/EffortJointInterface</hardwareInterface>
            <mechanicalReduction>1</mechanicalReduction>
        </actuator>
    </transmission>
    <transmission name="trans_robotA_joint_3">
        <type>transmission_interface/SimpleTransmission</type>
        <joint name="robotA_joint_3">
            <hardwareInterface>hardware_interface/EffortJointInterface</hardwareInterface>
        </joint>
        <actuator name="robotA_joint_3_motor">
            <hardwareInterface>hardware_interface/EffortJointInterface</hardwareInterface>
            <mechanicalReduction>1</mechanicalReduction>
        </actuator>
    </transmission>
    <transmission name="trans_robotA_joint_4">
        <type>transmission_interface/SimpleTransmission</type>
        <joint name="robotA_joint_4">
            <hardwareInterface>hardware_interface/EffortJointInterface</hardwareInterface>
        </joint>
        <actuator name="robotA_joint_4_motor">
            <hardwareInterface>hardware_interface/EffortJointInterface</hardwareInterface>
            <mechanicalReduction>1</mechanicalReduction>
        </actuator>
    </transmission>
    <transmission name="trans_robotA_joint_5">
        <type>transmission_interface/SimpleTransmission</type>
        <joint name="robotA_joint_5">
            <hardwareInterface>hardware_interface/EffortJointInterface</hardwareInterface>
        </joint>
        <actuator name="robotA_joint_5_motor">
            <hardwareInterface>hardware_interface/EffortJointInterface</hardwareInterface>
            <mechanicalReduction>1</mechanicalReduction>
        </actuator>
    </transmission>
    <transmission name="trans_robotA_joint_6">
        <type>transmission_interface/SimpleTransmission</type>
        <joint name="robotA_joint_6">
            <hardwareInterface>hardware_interface/EffortJointInterface</hardwareInterface>
        </joint>
        <actuator name="robotA_joint_6_motor">
            <hardwareInterface>hardware_interface/EffortJointInterface</hardwareInterface>
            <mechanicalReduction>1</mechanicalReduction>
        </actuator>
    </transmission>
    <transmission name="trans_robotB_joint_1">
        <type>transmission_interface/SimpleTransmission</type>
        <joint name="robotB_joint_1">
            <hardwareInterface>hardware_interface/EffortJointInterface</hardwareInterface>
        </joint>
        <actuator name="robotB_joint_1_motor">
            <hardwareInterface>hardware_interface/EffortJointInterface</hardwareInterface>
            <mechanicalReduction>1</mechanicalReduction>
        </actuator>
    </transmission>
    <transmission name="trans_robotB_joint_2">
        <type>transmission_interface/SimpleTransmission</type>
        <joint name="robotB_joint_2">
            <hardwareInterface>hardware_interface/EffortJointInterface</hardwareInterface>
        </joint>
        <actuator name="robotB_joint_2_motor">
            <hardwareInterface>hardware_interface/EffortJointInterface</hardwareInterface>
            <mechanicalReduction>1</mechanicalReduction>
        </actuator>
    </transmission>
    <transmission name="trans_robotB_joint_3">
        <type>transmission_interface/SimpleTransmission</type>
        <joint name="robotB_joint_3">
            <hardwareInterface>hardware_interface/EffortJointInterface</hardwareInterface>
        </joint>
        <actuator name="robotB_joint_3_motor">
            <hardwareInterface>hardware_interface/EffortJointInterface</hardwareInterface>
            <mechanicalReduction>1</mechanicalReduction>
        </actuator>
    </transmission>
    <transmission name="trans_robotB_joint_4">
        <type>transmission_interface/SimpleTransmission</type>
        <joint name="robotB_joint_4">
            <hardwareInterface>hardware_interface/EffortJointInterface</hardwareInterface>
        </joint>
        <actuator name="robotB_joint_4_motor">
            <hardwareInterface>hardware_interface/EffortJointInterface</hardwareInterface>
            <mechanicalReduction>1</mechanicalReduction>
        </actuator>
    </transmission>
    <transmission name="trans_robotB_joint_5">
        <type>transmission_interface/SimpleTransmission</type>
        <joint name="robotB_joint_5">
            <hardwareInterface>hardware_interface/EffortJointInterface</hardwareInterface>
        </joint>
        <actuator name="robotB_joint_5_motor">
            <hardwareInterface>hardware_interface/EffortJointInterface</hardwareInterface>
            <mechanicalReduction>1</mechanicalReduction>
        </actuator>
    </transmission>
    <transmission name="trans_robotB_joint_6">
        <type>transmission_interface/SimpleTransmission</type>
        <joint name="robotB_joint_6">
            <hardwareInterface>hardware_interface/EffortJointInterface</hardwareInterface>
        </joint>
        <actuator name="robotB_joint_6_motor">
            <hardwareInterface>hardware_interface/EffortJointInterface</hardwareInterface>
            <mechanicalReduction>1</mechanicalReduction>
        </actuator>
    </transmission>
    <gazebo>
        <plugin name="gazebo_ros_control">
            <robotNamespace>/</robotNamespace>
        </plugin>
    </gazebo>
</robot>

