<?xml version='1.0' encoding='utf-8'?>
<robot name="ABB_IRB2600_12_185">

	<link name="base_link">
		<visual>
			<origin xyz="0 0 0" quat="0 0 0 1" />
			<geometry>
				<mesh filename="package://abb_irb_2600_12_185_support/meshes/visual/BaseLink.stl" />
			</geometry>
			<xacro:material_abb_dark_gray />
		</visual>
		<collision>
			<origin xyz="0 0 0" quat="0 0 0 1" />
			<geometry>
				<mesh filename="package://abb_irb_2600_12_185_support/meshes/collision/BaseLink.stl" />
			</geometry>
		</collision>
	</link>
	<link name="link_1">
		<visual>
			<origin xyz="0 0 -0.445" quat="0 0 0 1" />
			<geometry>
				<mesh filename="package://abb_irb_2600_12_185_support/meshes/visual/Link1.stl" />
			</geometry>
			<xacro:material_abb_dark_gray />
		</visual>
		<collision>
			<origin xyz="0 0 -0.445" quat="0 0 0 1" />
			<geometry>
				<mesh filename="package://abb_irb_2600_12_185_support/meshes/collision/Link1.stl" />
			</geometry>
		</collision>
	</link>
	<link name="link_2">
		<visual>
			<origin xyz="-0.15 0 -0.445" quat="0 0 0 1" />
			<geometry>
				<mesh filename="package://abb_irb_2600_12_185_support/meshes/visual/Link2.stl" />
			</geometry>
			<xacro:material_abb_dark_gray />
		</visual>
		<collision>
			<origin xyz="-0.15 0 -0.445" quat="0 0 0 1" />
			<geometry>
				<mesh filename="package://abb_irb_2600_12_185_support/meshes/collision/Link2.stl" />
			</geometry>
		</collision>
	</link>
	<link name="link_3">
		<visual>
			<origin xyz="-0.15 0 -1.345" quat="0 0 0 1" />
			<geometry>
				<mesh filename="package://abb_irb_2600_12_185_support/meshes/visual/Link3.stl" />
			</geometry>
			<xacro:material_abb_dark_gray />
		</visual>
		<collision>
			<origin xyz="-0.15 0 -1.345" quat="0 0 0 1" />
			<geometry>
				<mesh filename="package://abb_irb_2600_12_185_support/meshes/collision/Link3.stl" />
			</geometry>
		</collision>
	</link>
	<link name="link_4">
		<visual>
			<origin xyz="-0.15 0 -1.46" quat="0 0 0 1" />
			<geometry>
				<mesh filename="package://abb_irb_2600_12_185_support/meshes/visual/Link4.stl" />
			</geometry>
			<xacro:material_abb_dark_gray />
		</visual>
		<collision>
			<origin xyz="-0.15 0 -1.46" quat="0 0 0 1" />
			<geometry>
				<mesh filename="package://abb_irb_2600_12_185_support/meshes/collision/Link4.stl" />
			</geometry>
		</collision>
	</link>
	<link name="link_5">
		<visual>
			<origin xyz="-0.945 0 -1.46" quat="0 0 0 1" />
			<geometry>
				<mesh filename="package://abb_irb_2600_12_185_support/meshes/visual/Link5.stl" />
			</geometry>
			<xacro:material_abb_dark_gray />
		</visual>
		<collision>
			<origin xyz="-0.945 0 -1.46" quat="0 0 0 1" />
			<geometry>
				<mesh filename="package://abb_irb_2600_12_185_support/meshes/collision/Link5.stl" />
			</geometry>
		</collision>
	</link>
	<link name="link_6">
		<visual>
			<origin xyz="-1.03 0 -1.46" quat="0 0 0 1" />
			<geometry>
				<mesh filename="package://abb_irb_2600_12_185_support/meshes/visual/Link6.stl" />
			</geometry>
			<xacro:material_abb_dark_gray />
		</visual>
		<collision>
			<origin xyz="-1.03 0 -1.46" quat="0 0 0 1" />
			<geometry>
				<mesh filename="package://abb_irb_2600_12_185_support/meshes/collision/Link6.stl" />
			</geometry>
		</collision>
	</link>
    <!-- end of link list -->

    <!-- joint list -->
	<joint name="Joint1" type="revolute">
		<axis xyz="0.000 0.000 1.000" />
		<parent link="base_link" />
		<child link="link_1" />
		<origin xyz="0.000 0.000 0.445" quat="0 0 0 1"/>
		<limit lower="-3.1215" upper="3.12159" velocity="3.054" acceleration="15.27" effort="0.0" />
        <home_position value="0" />
	</joint>
	<joint name="Joint2" type="revolute">
		<axis xyz="0.000 1.000 0.000" />
		<parent link="link_1" />
		<child link="link_2" />
		<origin xyz="0.150 0.000 0.000" quat="0 0 0 1"/>
		<limit lower="-1.638" upper="2.685" velocity="3.054" acceleration="15.27" effort="0.0" />
        <home_position value="0" />
	</joint>
	<joint name="Joint3" type="revolute">
		<axis xyz="0.000 1.000 0.000" />
		<parent link="link_2" />
		<child link="link_3" />
		<origin xyz="0.000 0.000 0.900" quat="0 0 0 1" />
		<limit lower="-3.12159" upper="1.289" velocity="3.054" acceleration="15.27" effort="0.0"  />
        <home_position value="0" />
	</joint>
	<joint name="Joint4" type="revolute">
		<axis xyz="1.000 0.000 0.000" />
		<parent link="link_3" />
		<child link="link_4" />
		<origin xyz="0.000 0.000 0.115" quat="0 0 0 1" />
		<limit lower="-6.961" upper="6.961" velocity="6.283" acceleration="31.4150" effort="0.0" />
        <home_position value="0" />
	</joint>
	<joint name="Joint5" type="revolute">
		<axis xyz="0.000 1.000 0.000" />
		<parent link="link_4" />
		<child link="link_5" />
		<origin xyz="0.795 0.000 0.000" quat="0 0 0 1" />
		<limit lower="-2.074" upper="2.074" velocity="6.283" acceleration="31.4150" effort="0.0" />
        <home_position value="1.5708" />
	</joint>
	<joint name="Joint6" type="revolute">
		<axis xyz="1.000 0.000 0.000" />
		<parent link="link_5" />
		<child link="link_6" />
		<origin xyz="0.085 0.000 0.000" quat="0 0 0 1" />
		<limit lower="-6.961" upper="6.961" velocity="8.727" acceleration="43.6350" effort="0.0" />
        <home_position value="0" />
	</joint>
    <!-- end of joint list -->
	<!-- ROS-Industrial 'base' frame: base_link to ABB World Coordinates transform -->
	<link name="base"/>
	<joint name="base_link-base" type="fixed">
		<origin rpy="0 0 0" xyz="0 0 0"/>
		<parent link="base_link"/>
		<child link="base"/>
	</joint>
	<!-- ROS-Industrial 'flange' frame: attachment point for EEF models -->
	<link name="flange"/>
	<joint name="joint_6-flange" type="fixed">
		<origin rpy="0 0 0" xyz="0 0 0"/>
		<parent link="link_6"/>
		<child link="flange"/>
	</joint>
	<!-- ROS-Industrial 'tool0' frame: all-zeros tool frame -->
	<link name="tool0"/>
	<joint name="flange-tool0" type="fixed">
		<origin rpy="0 1.57079632679 0" xyz="0 0 0"/>
		<parent link="flange"/>
		<child link="tool0"/>
	</joint>
</robot>